<?xml version="1.0" encoding="utf-8"?>
<!-- =================================================================================== -->
<!-- |    This document was autogenerated by xacro from antobot_vector.xacro           | -->
<!-- |    EDITING THIS FILE BY HAND IS NOT RECOMMENDED                                 | -->
<!-- =================================================================================== -->
<robot name="antobot_vector">
  <!-- color   -->
  <material name="green">
    <color rgba="0.0 0.8 0.0 1.0"/>
  </material>
  <material name="yellow">
    <color rgba="1 0.4 0 1"/>
  </material>
  <material name="black">
    <color rgba="0 0 0 0.95"/>
  </material>
  <material name="gray">
    <color rgba="0.75 0.75 0.75 1"/>
  </material>
  <material name="LightGrey">
    <color rgba="0.96 0.96 0.96 0.5"/>
  </material>
  <material name="blue">
    <color rgba="0 0 0.8 0.5"/>
  </material>

  <!-- base_footprint -->
  <link name="base_footprint">
    <visual>
      <origin rpy="0 0 0" xyz=" 0 0 0"/>
      <geometry>
        <box size="0.01 0.01 0.01"/>
      </geometry>
      <material name="gray"/>
    </visual>
  </link>

  <!-- base_link -->
  <link name="base_link">
    <visual>
      <origin rpy="0 0 0" xyz=" 0 0 0"/>
      <geometry>
        <box size="1.456 0.57 0.39"/>
      </geometry>
      <material name="blue"/>
    </visual>
  </link>

  <!-- base_base_joint -->
  <joint name="base_base_joint" type="fixed">
    <origin rpy="0 0 0" xyz="0 0 -0.215"/>
    <parent link="base_link"/>
    <child link="base_footprint"/>
  </joint>

  <!-- imu_link -->
  <link name="imu_link">
    <visual>
      <origin rpy="0 0 0" xyz="0 0 0"/>
      <geometry>
        <box size="0.1 0.2 0.06"/>
      </geometry>
      <material name="yellow"/>
    </visual>
  </link>
  
  <joint name="imu_joint" type="fixed">
    <origin rpy="0 0 0" xyz="-0.36 0 -0.185"/>
    <parent link="base_link"/>
    <child link="imu_link"/>
  </joint>

  <!-- lidar_support_link -->
  <link name="lidar_support_link">
    <visual>
      <origin rpy="0 0 0" xyz="0 0 0"/>
      <geometry>
        <cylinder length="0.08" radius="0.1"/>
      </geometry>
      <material name="gray"/>
    </visual>
  </link>

  <!-- lidar_support_joint -->
  <joint name="lidar_support_joint" type="fixed">
    <origin rpy="0 0 0" xyz="-0.16 0 0.23"/>
    <parent link="base_link"/>
    <child link="lidar_support_link"/>
  </joint>

  <joint name="left_front_wheel_joint" type="continuous">
    <origin rpy="0 0 0" xyz="0.52 0.285 -0.195"/>
    <parent link="base_link"/>
    <child link="left_front_wheel_link"/>
    <axis xyz="0 1 0"/>
  </joint>

  <link name="left_front_wheel_link">
    <visual>
      <origin rpy="1.570795 0 0" xyz="0 0 0"/>
      <geometry>
        <cylinder length="0.1" radius="0.2"/>
      </geometry>
      <material name="black"/>
    </visual>
  </link>
  
  <joint name="left_back_wheel_joint" type="continuous">
    <origin rpy="0 0 0" xyz="-0.52 0.285 -0.195"/>
    <parent link="base_link"/>
    <child link="left_back_wheel_link"/>
    <axis xyz="0 1 0"/>
  </joint>

  <link name="left_back_wheel_link">
    <visual>
      <origin rpy="1.570795 0 0" xyz="0 0 0"/>
      <geometry>
        <cylinder length="0.1" radius="0.2"/>
      </geometry>
      <material name="black"/>
    </visual>
  </link>
 
  <joint name="right_front_wheel_joint" type="continuous">
    <origin rpy="0 0 0" xyz="0.52 -0.285 -0.195"/>
    <parent link="base_link"/>
    <child link="right_front_wheel_link"/>
    <axis xyz="0 1 0"/>
  </joint>

  <link name="right_front_wheel_link">
    <visual>
      <origin rpy="1.570795 0 0" xyz="0 0 0"/>
      <geometry>
        <cylinder length="0.1" radius="0.2"/>
      </geometry>
      <material name="black"/>
    </visual>
  </link>
 
  <joint name="right_back_wheel_joint" type="continuous">
    <origin rpy="0 0 0" xyz="-0.52 -0.285 -0.195"/>
    <parent link="base_link"/>
    <child link="right_back_wheel_link"/>
    <axis xyz="0 1 0"/>
  </joint>

  <link name="right_back_wheel_link">
    <visual>
      <origin rpy="1.570795 0 0" xyz="0 0 0"/>
      <geometry>
        <cylinder length="0.1" radius="0.2"/>
      </geometry>
      <material name="black"/>
    </visual>
  </link>

  <joint name="ls_c32_base_mount_joint" type="fixed">
    <origin rpy="0 0 0" xyz="0 0 0.085"/>
    <parent link="lidar_support_link"/>
    <child link="ls_c32_base_link"/>

  </joint>
  <link name="ls_c32_base_link">
    <visual>
      <geometry>
        <mesh filename="package://velodyne_description/meshes/HDL32E_base.dae"/>
      </geometry>
    </visual>
  </link>

  <joint name="ls_c32_base_scan_joint" type="fixed">
    <origin rpy="0 0 0" xyz="0 0 0.09081"/>
    <parent link="ls_c32_base_link"/>
    <child link="ls_c32"/>
  </joint>

  <link name="ls_c32">
    <visual>
      <origin rpy="0 0 0" xyz="0 0 -0.09081"/>
      <geometry>
        <mesh filename="package://velodyne_description/meshes/HDL32E_scan.dae"/>
      </geometry>
    </visual>
  </link>
</robot>

